Watching for file changes with StatReloader
Exception in thread django-main-thread:
Traceback (most recent call last):
  File "/usr/lib/python3.10/threading.py", line 1016, in _bootstrap_inner
    self.run()
  File "/usr/lib/python3.10/threading.py", line 953, in run
    self._target(*self._args, **self._kwargs)
  File "/home/schwitaaniyer/phoenix/venv/lib/python3.10/site-packages/django/utils/autoreload.py", line 64, in wrapper
    fn(*args, **kwargs)
  File "/home/schwitaaniyer/phoenix/venv/lib/python3.10/site-packages/django/core/management/commands/runserver.py", line 134, in inner_run
    self.check(**check_kwargs)
  File "/home/schwitaaniyer/phoenix/venv/lib/python3.10/site-packages/django/core/management/base.py", line 492, in check
    all_issues = checks.run_checks(
  File "/home/schwitaaniyer/phoenix/venv/lib/python3.10/site-packages/django/core/checks/registry.py", line 89, in run_checks
    new_errors = check(app_configs=app_configs, databases=databases)
  File "/home/schwitaaniyer/phoenix/venv/lib/python3.10/site-packages/django/core/checks/urls.py", line 16, in check_url_config
    return check_resolver(resolver)
  File "/home/schwitaaniyer/phoenix/venv/lib/python3.10/site-packages/django/core/checks/urls.py", line 26, in check_resolver
    return check_method()
  File "/home/schwitaaniyer/phoenix/venv/lib/python3.10/site-packages/django/urls/resolvers.py", line 531, in check
    for pattern in self.url_patterns:
  File "/home/schwitaaniyer/phoenix/venv/lib/python3.10/site-packages/django/utils/functional.py", line 47, in __get__
    res = instance.__dict__[self.name] = self.func(instance)
  File "/home/schwitaaniyer/phoenix/venv/lib/python3.10/site-packages/django/urls/resolvers.py", line 718, in url_patterns
    patterns = getattr(self.urlconf_module, "urlpatterns", self.urlconf_module)
  File "/home/schwitaaniyer/phoenix/venv/lib/python3.10/site-packages/django/utils/functional.py", line 47, in __get__
    res = instance.__dict__[self.name] = self.func(instance)
  File "/home/schwitaaniyer/phoenix/venv/lib/python3.10/site-packages/django/urls/resolvers.py", line 711, in urlconf_module
    return import_module(self.urlconf_name)
  File "/usr/lib/python3.10/importlib/__init__.py", line 126, in import_module
    return _bootstrap._gcd_import(name[level:], package, level)
  File "<frozen importlib._bootstrap>", line 1050, in _gcd_import
  File "<frozen importlib._bootstrap>", line 1027, in _find_and_load
  File "<frozen importlib._bootstrap>", line 1006, in _find_and_load_unlocked
  File "<frozen importlib._bootstrap>", line 688, in _load_unlocked
  File "<frozen importlib._bootstrap_external>", line 883, in exec_module
  File "<frozen importlib._bootstrap>", line 241, in _call_with_frames_removed
  File "/home/schwitaaniyer/phoenix/phoenix/urls.py", line 11, in <module>
    path('network/', include('network.urls')),
  File "/home/schwitaaniyer/phoenix/venv/lib/python3.10/site-packages/django/urls/conf.py", line 39, in include
    urlconf_module = import_module(urlconf_module)
  File "/usr/lib/python3.10/importlib/__init__.py", line 126, in import_module
    return _bootstrap._gcd_import(name[level:], package, level)
  File "<frozen importlib._bootstrap>", line 1050, in _gcd_import
  File "<frozen importlib._bootstrap>", line 1027, in _find_and_load
  File "<frozen importlib._bootstrap>", line 1006, in _find_and_load_unlocked
  File "<frozen importlib._bootstrap>", line 688, in _load_unlocked
  File "<frozen importlib._bootstrap_external>", line 883, in exec_module
  File "<frozen importlib._bootstrap>", line 241, in _call_with_frames_removed
  File "/home/schwitaaniyer/phoenix/network/urls.py", line 2, in <module>
    from .views import (
  File "/home/schwitaaniyer/phoenix/network/views.py", line 600
    bond = form.save(commit=False)
IndentationError: unexpected indent
/home/schwitaaniyer/phoenix/network/views.py changed, reloading.
Performing system checks...

Watching for file changes with StatReloader
System check identified some issues:

WARNINGS:
?: (urls.W005) URL namespace 'dashboard' isn't unique. You may not be able to reverse all URLs in this namespace

System check identified 1 issue (0 silenced).
/home/schwitaaniyer/phoenix/network/views.py changed, reloading.
Performing system checks...

June 20, 2025 - 13:41:26
Django version 5.2, using settings 'phoenix.settings'
Starting development server at http://0.0.0.0:8000/
Quit the server with CONTROL-C.

WARNING: This is a development server. Do not use it in a production setting. Use a production WSGI or ASGI server instead.
For more information on production servers see: https://docs.djangoproject.com/en/5.2/howto/deployment/
Watching for file changes with StatReloader
System check identified some issues:

WARNINGS:
?: (urls.W005) URL namespace 'dashboard' isn't unique. You may not be able to reverse all URLs in this namespace

System check identified 1 issue (0 silenced).
Watching for file changes with StatReloader
System check identified some issues:

WARNINGS:
?: (urls.W005) URL namespace 'dashboard' isn't unique. You may not be able to reverse all URLs in this namespace

System check identified 1 issue (0 silenced).
[20/Jun/2025 13:42:30] "GET /dashboard/ HTTP/1.1" 200 29941
[20/Jun/2025 13:42:31] "GET /dashboard/api/metrics/ HTTP/1.1" 200 654
[20/Jun/2025 13:42:33] "GET /dashboard/api/metrics/ HTTP/1.1" 200 655
[20/Jun/2025 13:42:35] "GET /dashboard/api/metrics/ HTTP/1.1" 200 655
[20/Jun/2025 13:42:37] "GET /dashboard/api/metrics/ HTTP/1.1" 200 656
[20/Jun/2025 13:42:39] "GET /dashboard/api/metrics/ HTTP/1.1" 200 656
[20/Jun/2025 13:42:41] "GET /dashboard/api/metrics/ HTTP/1.1" 200 656
[20/Jun/2025 13:42:43] "GET /dashboard/api/metrics/ HTTP/1.1" 200 655
[20/Jun/2025 13:42:45] "GET /dashboard/api/metrics/ HTTP/1.1" 200 655
[20/Jun/2025 13:42:47] "GET /dashboard/api/metrics/ HTTP/1.1" 200 653
[20/Jun/2025 13:42:49] "GET /dashboard/api/metrics/ HTTP/1.1" 200 653
[20/Jun/2025 13:42:51] "GET /dashboard/api/metrics/ HTTP/1.1" 200 654
[20/Jun/2025 13:42:53] "GET /dashboard/api/metrics/ HTTP/1.1" 200 655
[20/Jun/2025 13:42:55] "GET /dashboard/api/metrics/ HTTP/1.1" 200 656
[20/Jun/2025 13:42:57] "GET /dashboard/api/metrics/ HTTP/1.1" 200 654
[20/Jun/2025 13:42:59] "GET /dashboard/api/metrics/ HTTP/1.1" 200 655
[20/Jun/2025 13:43:01] "GET /dashboard/api/metrics/ HTTP/1.1" 200 655
[20/Jun/2025 13:43:03] "GET /dashboard/api/metrics/ HTTP/1.1" 200 655
[20/Jun/2025 13:43:05] "GET /dashboard/api/metrics/ HTTP/1.1" 200 656
[20/Jun/2025 13:43:07] "GET /dashboard/api/metrics/ HTTP/1.1" 200 653
[20/Jun/2025 13:43:09] "GET /dashboard/api/metrics/ HTTP/1.1" 200 654
[20/Jun/2025 13:43:11] "GET /dashboard/api/metrics/ HTTP/1.1" 200 655
[20/Jun/2025 13:43:13] "GET /dashboard/api/metrics/ HTTP/1.1" 200 656
[20/Jun/2025 13:43:15] "GET /dashboard/api/metrics/ HTTP/1.1" 200 656
[20/Jun/2025 13:43:17] "GET /dashboard/api/metrics/ HTTP/1.1" 200 656
[20/Jun/2025 13:43:19] "GET /dashboard/api/metrics/ HTTP/1.1" 200 656
[20/Jun/2025 13:43:21] "GET /dashboard/api/metrics/ HTTP/1.1" 200 656
[20/Jun/2025 13:43:23] "GET /dashboard/api/metrics/ HTTP/1.1" 200 655
/home/schwitaaniyer/phoenix/network/views.py changed, reloading.
Performing system checks...

June 20, 2025 - 13:41:54
Django version 5.2, using settings 'phoenix.settings'
Starting development server at http://0.0.0.0:8000/
Quit the server with CONTROL-C.

WARNING: This is a development server. Do not use it in a production setting. Use a production WSGI or ASGI server instead.
For more information on production servers see: https://docs.djangoproject.com/en/5.2/howto/deployment/
Watching for file changes with StatReloader
Exception in thread django-main-thread:
Traceback (most recent call last):
  File "/usr/lib/python3.10/threading.py", line 1016, in _bootstrap_inner
    self.run()
  File "/usr/lib/python3.10/threading.py", line 953, in run
    self._target(*self._args, **self._kwargs)
  File "/home/schwitaaniyer/phoenix/venv/lib/python3.10/site-packages/django/utils/autoreload.py", line 64, in wrapper
    fn(*args, **kwargs)
  File "/home/schwitaaniyer/phoenix/venv/lib/python3.10/site-packages/django/core/management/commands/runserver.py", line 134, in inner_run
    self.check(**check_kwargs)
  File "/home/schwitaaniyer/phoenix/venv/lib/python3.10/site-packages/django/core/management/base.py", line 492, in check
    all_issues = checks.run_checks(
  File "/home/schwitaaniyer/phoenix/venv/lib/python3.10/site-packages/django/core/checks/registry.py", line 89, in run_checks
    new_errors = check(app_configs=app_configs, databases=databases)
  File "/home/schwitaaniyer/phoenix/venv/lib/python3.10/site-packages/django/core/checks/urls.py", line 16, in check_url_config
    return check_resolver(resolver)
  File "/home/schwitaaniyer/phoenix/venv/lib/python3.10/site-packages/django/core/checks/urls.py", line 26, in check_resolver
    return check_method()
  File "/home/schwitaaniyer/phoenix/venv/lib/python3.10/site-packages/django/urls/resolvers.py", line 531, in check
    for pattern in self.url_patterns:
  File "/home/schwitaaniyer/phoenix/venv/lib/python3.10/site-packages/django/utils/functional.py", line 47, in __get__
    res = instance.__dict__[self.name] = self.func(instance)
  File "/home/schwitaaniyer/phoenix/venv/lib/python3.10/site-packages/django/urls/resolvers.py", line 718, in url_patterns
    patterns = getattr(self.urlconf_module, "urlpatterns", self.urlconf_module)
  File "/home/schwitaaniyer/phoenix/venv/lib/python3.10/site-packages/django/utils/functional.py", line 47, in __get__
    res = instance.__dict__[self.name] = self.func(instance)
  File "/home/schwitaaniyer/phoenix/venv/lib/python3.10/site-packages/django/urls/resolvers.py", line 711, in urlconf_module
    return import_module(self.urlconf_name)
  File "/usr/lib/python3.10/importlib/__init__.py", line 126, in import_module
    return _bootstrap._gcd_import(name[level:], package, level)
  File "<frozen importlib._bootstrap>", line 1050, in _gcd_import
  File "<frozen importlib._bootstrap>", line 1027, in _find_and_load
  File "<frozen importlib._bootstrap>", line 1006, in _find_and_load_unlocked
  File "<frozen importlib._bootstrap>", line 688, in _load_unlocked
  File "<frozen importlib._bootstrap_external>", line 883, in exec_module
  File "<frozen importlib._bootstrap>", line 241, in _call_with_frames_removed
  File "/home/schwitaaniyer/phoenix/phoenix/urls.py", line 11, in <module>
    path('network/', include('network.urls')),
  File "/home/schwitaaniyer/phoenix/venv/lib/python3.10/site-packages/django/urls/conf.py", line 39, in include
    urlconf_module = import_module(urlconf_module)
  File "/usr/lib/python3.10/importlib/__init__.py", line 126, in import_module
    return _bootstrap._gcd_import(name[level:], package, level)
  File "<frozen importlib._bootstrap>", line 1050, in _gcd_import
  File "<frozen importlib._bootstrap>", line 1027, in _find_and_load
  File "<frozen importlib._bootstrap>", line 1006, in _find_and_load_unlocked
  File "<frozen importlib._bootstrap>", line 688, in _load_unlocked
  File "<frozen importlib._bootstrap_external>", line 883, in exec_module
  File "<frozen importlib._bootstrap>", line 241, in _call_with_frames_removed
  File "/home/schwitaaniyer/phoenix/network/urls.py", line 2, in <module>
    from .views import (
  File "/home/schwitaaniyer/phoenix/network/views.py", line 600
    bond = form.save(commit=False)
IndentationError: unexpected indent
/home/schwitaaniyer/phoenix/phoenix/settings.py changed, reloading.
Performing system checks...

Watching for file changes with StatReloader
Exception in thread django-main-thread:
Traceback (most recent call last):
  File "/usr/lib/python3.10/threading.py", line 1016, in _bootstrap_inner
    self.run()
  File "/usr/lib/python3.10/threading.py", line 953, in run
    self._target(*self._args, **self._kwargs)
  File "/home/schwitaaniyer/phoenix/venv/lib/python3.10/site-packages/django/utils/autoreload.py", line 64, in wrapper
    fn(*args, **kwargs)
  File "/home/schwitaaniyer/phoenix/venv/lib/python3.10/site-packages/django/core/management/commands/runserver.py", line 134, in inner_run
    self.check(**check_kwargs)
  File "/home/schwitaaniyer/phoenix/venv/lib/python3.10/site-packages/django/core/management/base.py", line 492, in check
    all_issues = checks.run_checks(
  File "/home/schwitaaniyer/phoenix/venv/lib/python3.10/site-packages/django/core/checks/registry.py", line 89, in run_checks
    new_errors = check(app_configs=app_configs, databases=databases)
  File "/home/schwitaaniyer/phoenix/venv/lib/python3.10/site-packages/django/core/checks/urls.py", line 16, in check_url_config
    return check_resolver(resolver)
  File "/home/schwitaaniyer/phoenix/venv/lib/python3.10/site-packages/django/core/checks/urls.py", line 26, in check_resolver
    return check_method()
  File "/home/schwitaaniyer/phoenix/venv/lib/python3.10/site-packages/django/urls/resolvers.py", line 531, in check
    for pattern in self.url_patterns:
  File "/home/schwitaaniyer/phoenix/venv/lib/python3.10/site-packages/django/utils/functional.py", line 47, in __get__
    res = instance.__dict__[self.name] = self.func(instance)
  File "/home/schwitaaniyer/phoenix/venv/lib/python3.10/site-packages/django/urls/resolvers.py", line 718, in url_patterns
    patterns = getattr(self.urlconf_module, "urlpatterns", self.urlconf_module)
  File "/home/schwitaaniyer/phoenix/venv/lib/python3.10/site-packages/django/utils/functional.py", line 47, in __get__
    res = instance.__dict__[self.name] = self.func(instance)
  File "/home/schwitaaniyer/phoenix/venv/lib/python3.10/site-packages/django/urls/resolvers.py", line 711, in urlconf_module
    return import_module(self.urlconf_name)
  File "/usr/lib/python3.10/importlib/__init__.py", line 126, in import_module
    return _bootstrap._gcd_import(name[level:], package, level)
  File "<frozen importlib._bootstrap>", line 1050, in _gcd_import
  File "<frozen importlib._bootstrap>", line 1027, in _find_and_load
  File "<frozen importlib._bootstrap>", line 1006, in _find_and_load_unlocked
  File "<frozen importlib._bootstrap>", line 688, in _load_unlocked
  File "<frozen importlib._bootstrap_external>", line 883, in exec_module
  File "<frozen importlib._bootstrap>", line 241, in _call_with_frames_removed
  File "/home/schwitaaniyer/phoenix/phoenix/urls.py", line 11, in <module>
    path('network/', include('network.urls')),
  File "/home/schwitaaniyer/phoenix/venv/lib/python3.10/site-packages/django/urls/conf.py", line 39, in include
    urlconf_module = import_module(urlconf_module)
  File "/usr/lib/python3.10/importlib/__init__.py", line 126, in import_module
    return _bootstrap._gcd_import(name[level:], package, level)
  File "<frozen importlib._bootstrap>", line 1050, in _gcd_import
  File "<frozen importlib._bootstrap>", line 1027, in _find_and_load
  File "<frozen importlib._bootstrap>", line 1006, in _find_and_load_unlocked
  File "<frozen importlib._bootstrap>", line 688, in _load_unlocked
  File "<frozen importlib._bootstrap_external>", line 883, in exec_module
  File "<frozen importlib._bootstrap>", line 241, in _call_with_frames_removed
  File "/home/schwitaaniyer/phoenix/network/urls.py", line 2, in <module>
    from .views import (
  File "/home/schwitaaniyer/phoenix/network/views.py", line 600
    bond = form.save(commit=False)
IndentationError: unexpected indent
/home/schwitaaniyer/phoenix/phoenix/settings.py changed, reloading.
Performing system checks...

Watching for file changes with StatReloader
Exception in thread django-main-thread:
Traceback (most recent call last):
  File "/usr/lib/python3.10/threading.py", line 1016, in _bootstrap_inner
    self.run()
  File "/usr/lib/python3.10/threading.py", line 953, in run
    self._target(*self._args, **self._kwargs)
  File "/home/schwitaaniyer/phoenix/venv/lib/python3.10/site-packages/django/utils/autoreload.py", line 64, in wrapper
    fn(*args, **kwargs)
  File "/home/schwitaaniyer/phoenix/venv/lib/python3.10/site-packages/django/core/management/commands/runserver.py", line 134, in inner_run
    self.check(**check_kwargs)
  File "/home/schwitaaniyer/phoenix/venv/lib/python3.10/site-packages/django/core/management/base.py", line 492, in check
    all_issues = checks.run_checks(
  File "/home/schwitaaniyer/phoenix/venv/lib/python3.10/site-packages/django/core/checks/registry.py", line 89, in run_checks
    new_errors = check(app_configs=app_configs, databases=databases)
  File "/home/schwitaaniyer/phoenix/venv/lib/python3.10/site-packages/django/core/checks/urls.py", line 16, in check_url_config
    return check_resolver(resolver)
  File "/home/schwitaaniyer/phoenix/venv/lib/python3.10/site-packages/django/core/checks/urls.py", line 26, in check_resolver
    return check_method()
  File "/home/schwitaaniyer/phoenix/venv/lib/python3.10/site-packages/django/urls/resolvers.py", line 531, in check
    for pattern in self.url_patterns:
  File "/home/schwitaaniyer/phoenix/venv/lib/python3.10/site-packages/django/utils/functional.py", line 47, in __get__
    res = instance.__dict__[self.name] = self.func(instance)
  File "/home/schwitaaniyer/phoenix/venv/lib/python3.10/site-packages/django/urls/resolvers.py", line 718, in url_patterns
    patterns = getattr(self.urlconf_module, "urlpatterns", self.urlconf_module)
  File "/home/schwitaaniyer/phoenix/venv/lib/python3.10/site-packages/django/utils/functional.py", line 47, in __get__
    res = instance.__dict__[self.name] = self.func(instance)
  File "/home/schwitaaniyer/phoenix/venv/lib/python3.10/site-packages/django/urls/resolvers.py", line 711, in urlconf_module
    return import_module(self.urlconf_name)
  File "/usr/lib/python3.10/importlib/__init__.py", line 126, in import_module
    return _bootstrap._gcd_import(name[level:], package, level)
  File "<frozen importlib._bootstrap>", line 1050, in _gcd_import
  File "<frozen importlib._bootstrap>", line 1027, in _find_and_load
  File "<frozen importlib._bootstrap>", line 1006, in _find_and_load_unlocked
  File "<frozen importlib._bootstrap>", line 688, in _load_unlocked
  File "<frozen importlib._bootstrap_external>", line 883, in exec_module
  File "<frozen importlib._bootstrap>", line 241, in _call_with_frames_removed
  File "/home/schwitaaniyer/phoenix/phoenix/urls.py", line 11, in <module>
    path('network/', include('network.urls')),
  File "/home/schwitaaniyer/phoenix/venv/lib/python3.10/site-packages/django/urls/conf.py", line 39, in include
    urlconf_module = import_module(urlconf_module)
  File "/usr/lib/python3.10/importlib/__init__.py", line 126, in import_module
    return _bootstrap._gcd_import(name[level:], package, level)
  File "<frozen importlib._bootstrap>", line 1050, in _gcd_import
  File "<frozen importlib._bootstrap>", line 1027, in _find_and_load
  File "<frozen importlib._bootstrap>", line 1006, in _find_and_load_unlocked
  File "<frozen importlib._bootstrap>", line 688, in _load_unlocked
  File "<frozen importlib._bootstrap_external>", line 883, in exec_module
  File "<frozen importlib._bootstrap>", line 241, in _call_with_frames_removed
  File "/home/schwitaaniyer/phoenix/network/urls.py", line 2, in <module>
    from .views import (
  File "/home/schwitaaniyer/phoenix/network/views.py", line 600
    bond = form.save(commit=False)
IndentationError: unexpected indent
/home/schwitaaniyer/phoenix/network/views.py changed, reloading.
Performing system checks...

Watching for file changes with StatReloader
System check identified some issues:

WARNINGS:
?: (urls.W005) URL namespace 'dashboard' isn't unique. You may not be able to reverse all URLs in this namespace

System check identified 1 issue (0 silenced).
Error: That port is already in use.
